<?xml version="1.0" encoding="UTF-8"?>
<!-- Generated by org.testng.reporters.JUnitReportReporter -->
<testsuite hostname="DESKTOP-MN86ODD" failures="1" tests="2" name="sZephyr_testcases.TC08_Pairing_BlewithoutRouter" time="435.788" errors="0" timestamp="2024-12-21T17:44:11 IST" skipped="1">
  <testcase classname="sZephyr_testcases.TC08_Pairing_BlewithoutRouter" name="removerepair" time="112.113">
    <failure message="Failed due to this exception" type="java.lang.AssertionError">
      <![CDATA[java.lang.AssertionError: Failed due to this exception
at org.testng.Assert.fail(Assert.java:99)
at sZephyr_testcases.TC08_Pairing_BlewithoutRouter.removerepair(TC08_Pairing_BlewithoutRouter.java:142)
at java.base/jdk.internal.reflect.DirectMethodHandleAccessor.invoke(DirectMethodHandleAccessor.java:103)
at java.base/java.lang.reflect.Method.invoke(Method.java:580)
at org.testng.internal.invokers.MethodInvocationHelper.invokeMethod(MethodInvocationHelper.java:139)
at org.testng.internal.invokers.TestInvoker.invokeMethod(TestInvoker.java:664)
at org.testng.internal.invokers.TestInvoker.retryFailed(TestInvoker.java:249)
at org.testng.internal.invokers.MethodRunner.runInSequence(MethodRunner.java:76)
at org.testng.internal.invokers.TestInvoker$MethodInvocationAgent.invoke(TestInvoker.java:961)
at org.testng.internal.invokers.TestInvoker.invokeTestMethods(TestInvoker.java:201)
at org.testng.internal.invokers.TestMethodWorker.invokeTestMethods(TestMethodWorker.java:148)
at org.testng.internal.invokers.TestMethodWorker.run(TestMethodWorker.java:128)
at java.base/java.util.ArrayList.forEach(ArrayList.java:1596)
at org.testng.TestRunner.privateRun(TestRunner.java:819)
at org.testng.TestRunner.run(TestRunner.java:619)
at org.testng.SuiteRunner.runTest(SuiteRunner.java:443)
at org.testng.SuiteRunner.runSequentially(SuiteRunner.java:437)
at org.testng.SuiteRunner.privateRun(SuiteRunner.java:397)
at org.testng.SuiteRunner.run(SuiteRunner.java:336)
at org.testng.SuiteRunnerWorker.runSuite(SuiteRunnerWorker.java:52)
at org.testng.SuiteRunnerWorker.run(SuiteRunnerWorker.java:95)
at org.testng.TestNG.runSuitesSequentially(TestNG.java:1301)
at org.testng.TestNG.runSuitesLocally(TestNG.java:1228)
at org.testng.TestNG.runSuites(TestNG.java:1134)
at org.testng.TestNG.run(TestNG.java:1101)
at org.testng.remote.AbstractRemoteTestNG.run(AbstractRemoteTestNG.java:115)
at org.testng.remote.RemoteTestNG.initAndRun(RemoteTestNG.java:293)
at org.testng.remote.RemoteTestNG.main(RemoteTestNG.java:91)
Caused by: java.lang.RuntimeException: FAILED
at utils.Reporter.reportStep(Reporter.java:53)
at wrappers.GenericWrappers.clickbyXpath(GenericWrappers.java:207)
at pages.AddDevicePage.startPairingButton(AddDevicePage.java:314)
at pages.AddDevicePage.proceedToAddDevice(AddDevicePage.java:646)
at pages.AddDevicePage.initiatepairing(AddDevicePage.java:628)
at pages.AddDevicePage.pair(AddDevicePage.java:584)
at sZephyr_testcases.TC08_Pairing_BlewithoutRouter.removerepair(TC08_Pairing_BlewithoutRouter.java:58)
... 26 more
]]>
    </failure>
  </testcase> <!-- removerepair -->
  <testcase classname="sZephyr_testcases.TC08_Pairing_BlewithoutRouter" name="removerepair" time="323.675">
    <skipped/>
  </testcase> <!-- removerepair -->
</testsuite> <!-- sZephyr_testcases.TC08_Pairing_BlewithoutRouter -->
